2021-04-04 23:13:54,376 - app - ERROR - Traceback (most recent call last):
  File "C:\Users\aroue\Downloads\Documents\@ML\notable-flask\melody.py", line 33, in generate_WAV
    audio =  np.hstack(audio)
  File "<__array_function__ internals>", line 5, in hstack
  File "C:\Users\aroue\anaconda3\lib\site-packages\numpy\core\shape_base.py", line 346, in hstack
    return _nx.concatenate(arrs, 1)
  File "<__array_function__ internals>", line 5, in concatenate
ValueError: need at least one array to concatenate

During handling of the above exception, another exception occurred:

Traceback (most recent call last):
  File "app.py", line 123, in predict
    text_files, fullsong_file, song_files = generate_WAV(all_predictions, "false")
  File "C:\Users\aroue\Downloads\Documents\@ML\notable-flask\melody.py", line 44, in generate_WAV
    raise ValueError("could not generate sinewave audio")
ValueError: could not generate sinewave audio

2021-04-04 23:20:45,194 - app - ERROR - ERROR: audio exceptioncould not generate sinewave audio
2021-04-04 23:20:45,353 - app - ERROR - Traceback (most recent call last):
  File "C:\Users\aroue\Downloads\Documents\@ML\notable-flask\melody.py", line 33, in generate_WAV
    audio =  np.hstack(audio)
  File "<__array_function__ internals>", line 5, in hstack
  File "C:\Users\aroue\anaconda3\lib\site-packages\numpy\core\shape_base.py", line 346, in hstack
    return _nx.concatenate(arrs, 1)
  File "<__array_function__ internals>", line 5, in concatenate
ValueError: need at least one array to concatenate

During handling of the above exception, another exception occurred:

Traceback (most recent call last):
  File "app.py", line 123, in predict
    text_files, fullsong_file, song_files = generate_WAV(all_predictions, "false")
  File "C:\Users\aroue\Downloads\Documents\@ML\notable-flask\melody.py", line 44, in generate_WAV
    raise ValueError("could not generate sinewave audio")
ValueError: could not generate sinewave audio

2021-04-04 23:32:29,725 - app - ERROR - ERROR: audio exceptioncould not generate sinewave audio
2021-04-04 23:32:29,744 - app - ERROR - Traceback (most recent call last):
  File "C:\Users\aroue\Downloads\Documents\@ML\notable-flask\melody.py", line 33, in generate_WAV
    audio =  np.hstack(audio)
  File "<__array_function__ internals>", line 5, in hstack
  File "C:\Users\aroue\anaconda3\lib\site-packages\numpy\core\shape_base.py", line 346, in hstack
    return _nx.concatenate(arrs, 1)
  File "<__array_function__ internals>", line 5, in concatenate
ValueError: need at least one array to concatenate

During handling of the above exception, another exception occurred:

Traceback (most recent call last):
  File "app.py", line 123, in predict
    text_files, fullsong_file, song_files = generate_WAV(all_predictions, "false")
  File "C:\Users\aroue\Downloads\Documents\@ML\notable-flask\melody.py", line 44, in generate_WAV
    raise ValueError("could not generate sinewave audio")
ValueError: could not generate sinewave audio

2021-04-04 23:36:53,775 - app - ERROR - ERROR: audio exceptioncould not generate sinewave audio
2021-04-04 23:36:53,775 - app - ERROR - Traceback (most recent call last):
  File "C:\Users\aroue\Downloads\Documents\@ML\notable-flask\melody.py", line 33, in generate_WAV
    audio =  np.hstack(audio)
  File "<__array_function__ internals>", line 5, in hstack
  File "C:\Users\aroue\anaconda3\lib\site-packages\numpy\core\shape_base.py", line 346, in hstack
    return _nx.concatenate(arrs, 1)
  File "<__array_function__ internals>", line 5, in concatenate
ValueError: need at least one array to concatenate

During handling of the above exception, another exception occurred:

Traceback (most recent call last):
  File "app.py", line 123, in predict
    text_files, fullsong_file, song_files = generate_WAV(all_predictions, "false")
  File "C:\Users\aroue\Downloads\Documents\@ML\notable-flask\melody.py", line 44, in generate_WAV
    raise ValueError("could not generate sinewave audio")
ValueError: could not generate sinewave audio

2021-04-04 23:38:23,668 - app - ERROR - ERROR: audio exceptioncould not generate sinewave audio
2021-04-04 23:38:23,668 - app - ERROR - Traceback (most recent call last):
  File "C:\Users\aroue\Downloads\Documents\@ML\notable-flask\melody.py", line 33, in generate_WAV
    audio =  np.hstack(audio)
  File "<__array_function__ internals>", line 5, in hstack
  File "C:\Users\aroue\anaconda3\lib\site-packages\numpy\core\shape_base.py", line 346, in hstack
    return _nx.concatenate(arrs, 1)
  File "<__array_function__ internals>", line 5, in concatenate
ValueError: need at least one array to concatenate

During handling of the above exception, another exception occurred:

Traceback (most recent call last):
  File "app.py", line 123, in predict
    text_files, fullsong_file, song_files = generate_WAV(all_predictions, "false")
  File "C:\Users\aroue\Downloads\Documents\@ML\notable-flask\melody.py", line 44, in generate_WAV
    raise ValueError("could not generate sinewave audio")
ValueError: could not generate sinewave audio

2021-04-04 23:51:07,402 - app - ERROR - ERROR: audio exceptioncould not generate sinewave audio
2021-04-04 23:51:07,402 - app - ERROR - Traceback (most recent call last):
  File "C:\Users\aroue\Downloads\Documents\@ML\notable-flask\melody.py", line 33, in generate_WAV
    audio =  np.hstack(audio)
  File "<__array_function__ internals>", line 5, in hstack
  File "C:\Users\aroue\anaconda3\lib\site-packages\numpy\core\shape_base.py", line 346, in hstack
    return _nx.concatenate(arrs, 1)
  File "<__array_function__ internals>", line 5, in concatenate
ValueError: need at least one array to concatenate

During handling of the above exception, another exception occurred:

Traceback (most recent call last):
  File "app.py", line 123, in predict
    text_files, fullsong_file, song_files = generate_WAV(all_predictions, "false")
  File "C:\Users\aroue\Downloads\Documents\@ML\notable-flask\melody.py", line 44, in generate_WAV
    raise ValueError("could not generate sinewave audio")
ValueError: could not generate sinewave audio

2021-04-04 23:51:43,227 - app - ERROR - ERROR: audio exceptioncould not generate sinewave audio
2021-04-04 23:51:43,227 - app - ERROR - Traceback (most recent call last):
  File "C:\Users\aroue\Downloads\Documents\@ML\notable-flask\melody.py", line 33, in generate_WAV
    audio =  np.hstack(audio)
  File "<__array_function__ internals>", line 5, in hstack
  File "C:\Users\aroue\anaconda3\lib\site-packages\numpy\core\shape_base.py", line 346, in hstack
    return _nx.concatenate(arrs, 1)
  File "<__array_function__ internals>", line 5, in concatenate
ValueError: need at least one array to concatenate

During handling of the above exception, another exception occurred:

Traceback (most recent call last):
  File "app.py", line 123, in predict
    text_files, fullsong_file, song_files = generate_WAV(all_predictions, "false")
  File "C:\Users\aroue\Downloads\Documents\@ML\notable-flask\melody.py", line 44, in generate_WAV
    raise ValueError("could not generate sinewave audio")
ValueError: could not generate sinewave audio

2021-04-07 16:27:27,581 - app - ERROR - ERROR: prediction exception Unable to determine storage type.
2021-04-07 16:27:28,075 - app - ERROR - Traceback (most recent call last):
  File "app.py", line 116, in predict
    all_predictions, segmented_staves = model.predict(cv_img)
  File "C:\Users\aroue\Downloads\Documents\@ML\notable-flask\ml_model.py", line 64, in predict
    segmented_staves = Slice(cv_img)
  File "C:\Users\aroue\Downloads\Documents\@ML\notable-flask\segmenter\slicer.py", line 106, in Slice
    segmented_staves.append(crop(img))
  File "C:\Users\aroue\Downloads\Documents\@ML\notable-flask\segmenter\commonfunctions.py", line 52, in crop
    with WI.from_array(img_mat) as wand_img:
  File "C:\Users\aroue\anaconda3\lib\site-packages\wand\image.py", line 9252, in from_array
    raise ValueError('Unable to determine storage type.')
ValueError: Unable to determine storage type.

2021-04-07 16:36:55,486 - app - ERROR - ERROR: audio exceptioncould not generate sinewave audio
2021-04-07 16:36:55,487 - app - ERROR - Traceback (most recent call last):
  File "C:\Users\aroue\Downloads\Documents\@ML\notable-flask\melody.py", line 33, in generate_WAV
    audio =  np.hstack(audio)
  File "<__array_function__ internals>", line 5, in hstack
  File "C:\Users\aroue\anaconda3\lib\site-packages\numpy\core\shape_base.py", line 346, in hstack
    return _nx.concatenate(arrs, 1)
  File "<__array_function__ internals>", line 5, in concatenate
ValueError: need at least one array to concatenate

During handling of the above exception, another exception occurred:

Traceback (most recent call last):
  File "app.py", line 123, in predict
    text_files, fullsong_file, song_files = generate_WAV(all_predictions, "false")
  File "C:\Users\aroue\Downloads\Documents\@ML\notable-flask\melody.py", line 44, in generate_WAV
    raise ValueError("could not generate sinewave audio")
ValueError: could not generate sinewave audio

