2021-04-03 17:34:47,387 - app - ERROR - Traceback (most recent call last):
  File "app.py", line 116, in predict
    all_predictions, segmented_staves = model.predict(cv_img)
  File "C:\Users\aroue\Downloads\Documents\@ML\notable-flask\ml_model.py", line 64, in predict
    segmented_staves = Slice(cv_img)
  File "C:\Users\aroue\Downloads\Documents\@ML\notable-flask\segmenter\slicer.py", line 84, in Slice
    raise ValueError("black pixel overflow")
ValueError: black pixel overflow

2021-04-03 17:34:57,935 - app - ERROR - ERROR: audio exceptioncould not generate sinewave audio
2021-04-03 17:34:57,935 - app - ERROR - Traceback (most recent call last):
  File "C:\Users\aroue\Downloads\Documents\@ML\notable-flask\melody.py", line 33, in generate_WAV
    audio =  np.hstack(audio)
  File "<__array_function__ internals>", line 5, in hstack
  File "C:\Users\aroue\anaconda3\lib\site-packages\numpy\core\shape_base.py", line 346, in hstack
    return _nx.concatenate(arrs, 1)
  File "<__array_function__ internals>", line 5, in concatenate
ValueError: need at least one array to concatenate

During handling of the above exception, another exception occurred:

Traceback (most recent call last):
  File "app.py", line 123, in predict
    text_files, fullsong_file, song_files = generate_WAV(all_predictions, "false")
  File "C:\Users\aroue\Downloads\Documents\@ML\notable-flask\melody.py", line 44, in generate_WAV
    raise ValueError("could not generate sinewave audio")
ValueError: could not generate sinewave audio

2021-04-03 17:35:09,224 - app - ERROR - ERROR: audio exceptioncould not generate sinewave audio
2021-04-03 17:35:09,225 - app - ERROR - Traceback (most recent call last):
  File "C:\Users\aroue\Downloads\Documents\@ML\notable-flask\melody.py", line 35, in generate_WAV
    audio *= 32767 / np.max(np.abs(audio))
  File "<__array_function__ internals>", line 5, in amax
  File "C:\Users\aroue\anaconda3\lib\site-packages\numpy\core\fromnumeric.py", line 2705, in amax
    return _wrapreduction(a, np.maximum, 'max', axis, None, out,
  File "C:\Users\aroue\anaconda3\lib\site-packages\numpy\core\fromnumeric.py", line 87, in _wrapreduction
    return ufunc.reduce(obj, axis, dtype, out, **passkwargs)
ValueError: zero-size array to reduction operation maximum which has no identity

During handling of the above exception, another exception occurred:

Traceback (most recent call last):
  File "app.py", line 123, in predict
    text_files, fullsong_file, song_files = generate_WAV(all_predictions, "false")
  File "C:\Users\aroue\Downloads\Documents\@ML\notable-flask\melody.py", line 44, in generate_WAV
    raise ValueError("could not generate sinewave audio")
ValueError: could not generate sinewave audio

2021-04-03 17:59:59,604 - app - ERROR - ERROR: prediction exception black pixel overflow
2021-04-03 17:59:59,682 - app - ERROR - Traceback (most recent call last):
  File "app.py", line 116, in predict
    all_predictions, segmented_staves = model.predict(cv_img)
  File "C:\Users\aroue\Downloads\Documents\@ML\notable-flask\ml_model.py", line 64, in predict
    segmented_staves = Slice(cv_img)
  File "C:\Users\aroue\Downloads\Documents\@ML\notable-flask\segmenter\slicer.py", line 84, in Slice
    raise ValueError("black pixel overflow")
ValueError: black pixel overflow

2021-04-03 18:19:43,610 - app - ERROR - ERROR: audio exceptioncould not generate sinewave audio
2021-04-03 18:19:43,647 - app - ERROR - Traceback (most recent call last):
  File "C:\Users\aroue\Downloads\Documents\@ML\notable-flask\melody.py", line 35, in generate_WAV
    audio *= 32767 / np.max(np.abs(audio))
  File "<__array_function__ internals>", line 5, in amax
  File "C:\Users\aroue\anaconda3\lib\site-packages\numpy\core\fromnumeric.py", line 2705, in amax
    return _wrapreduction(a, np.maximum, 'max', axis, None, out,
  File "C:\Users\aroue\anaconda3\lib\site-packages\numpy\core\fromnumeric.py", line 87, in _wrapreduction
    return ufunc.reduce(obj, axis, dtype, out, **passkwargs)
ValueError: zero-size array to reduction operation maximum which has no identity

During handling of the above exception, another exception occurred:

Traceback (most recent call last):
  File "app.py", line 123, in predict
    text_files, fullsong_file, song_files = generate_WAV(all_predictions, "false")
  File "C:\Users\aroue\Downloads\Documents\@ML\notable-flask\melody.py", line 44, in generate_WAV
    raise ValueError("could not generate sinewave audio")
ValueError: could not generate sinewave audio

2021-04-03 18:20:03,059 - app - ERROR - ERROR: prediction exception black pixel overflow
2021-04-03 18:20:03,093 - app - ERROR - Traceback (most recent call last):
  File "app.py", line 116, in predict
    all_predictions, segmented_staves = model.predict(cv_img)
  File "C:\Users\aroue\Downloads\Documents\@ML\notable-flask\ml_model.py", line 64, in predict
    segmented_staves = Slice(cv_img)
  File "C:\Users\aroue\Downloads\Documents\@ML\notable-flask\segmenter\slicer.py", line 84, in Slice
    raise ValueError("black pixel overflow")
ValueError: black pixel overflow

2021-04-03 18:21:23,696 - app - ERROR - ERROR: audio exceptioncould not generate sinewave audio
2021-04-03 18:21:23,696 - app - ERROR - Traceback (most recent call last):
  File "C:\Users\aroue\Downloads\Documents\@ML\notable-flask\melody.py", line 33, in generate_WAV
    audio =  np.hstack(audio)
  File "<__array_function__ internals>", line 5, in hstack
  File "C:\Users\aroue\anaconda3\lib\site-packages\numpy\core\shape_base.py", line 346, in hstack
    return _nx.concatenate(arrs, 1)
  File "<__array_function__ internals>", line 5, in concatenate
ValueError: need at least one array to concatenate

During handling of the above exception, another exception occurred:

Traceback (most recent call last):
  File "app.py", line 123, in predict
    text_files, fullsong_file, song_files = generate_WAV(all_predictions, "false")
  File "C:\Users\aroue\Downloads\Documents\@ML\notable-flask\melody.py", line 44, in generate_WAV
    raise ValueError("could not generate sinewave audio")
ValueError: could not generate sinewave audio

